<?xml version="1.0"?>
<!-- Revolute-Revolute Manipulator -->
<robot name="rrbot" xmlns:xacro="http://www.ros.org/wiki/xacro">

  <!-- Import all Gazebo-customization elements, including Gazebo colors -->
  <xacro:include filename="$(find rrbot_description)/urdf/rrbot.gazebo" />
  <!-- Import Rviz colors -->
  <xacro:include filename="$(find rrbot_description)/urdf/materials.xacro" />


  <!-- link 5: tool_wrist_caudier_link -->
    <link name="tool_wrist_caudier_link">
      <visual>
        <origin rpy="0.00 -1.5708 0.0" xyz="-0.0024 0.00 0.000"/>
        <geometry>
          <mesh filename="package://rrbot_description/meshes/tool_wrist_caudier_link_1.stl"/>
        </geometry>
        <material name="gray"><color rgba="0.5 0.5 0.9 1.0"/></material>
      </visual>
      <collision>
        <origin rpy="0.00 -1.5708 0.0" xyz="-0.0024 0.00 0.000"/>
        <geometry>
          <mesh filename="package://rrbot_description/meshes/tool_wrist_caudier_link_1.stl"/>
        </geometry>
      </collision>
    <inertial>
      <mass value="0.05"/>
      <inertia ixx="1.0" ixy="0.0" ixz="0.0" iyy="1.0" iyz="0.0" izz="1.0"/>
    </inertial>
    </link>

    <!-- joint 6: Tool wrist yaw joint -->
    <joint name="outer_wrist_yaw" type="revolute">
      <parent link="tool_wrist_caudier_link"/>
      <child link="tool_wrist_caudier_link_shaft"/>
      <axis xyz="0 0 1"/>
      <origin rpy="0.00 -1.5708 -1.5708" xyz="0.0091 0 0"/>
      <limit lower="-1.5707" upper="1.5707" velocity=".4" effort="1000"/>
    </joint>

    <!-- link 6: tool_wrist_caudier_link_shaft -->
    <link name="tool_wrist_caudier_link_shaft">
      <visual>
        <origin rpy="0.00 1.5708 0.0" xyz="0.0 -0.0002 0.000"/>
        <geometry>
          <mesh filename="package://rrbot_description/meshes/tool_wrist_caudier_link_1_shaft.stl"/>
        </geometry>
        <material name="gray"><color rgba="0.5 0.5 0.9 1.0"/></material>
      </visual>
      <collision>
        <origin rpy="0.00 1.5708 0.0" xyz="0.0 0.00 0.000"/>
        <geometry>
          <mesh filename="package://rrbot_description/meshes/tool_wrist_caudier_link_1_shaft.stl"/>
        </geometry>
      </collision>
    <inertial>
      <mass value="0.05"/>
      <inertia ixx="1.0" ixy="0.0" ixz="0.0" iyy="1.0" iyz="0.0" izz="1.0"/>
    </inertial>
    </link>  

    <!-- joint 7-0: Outer open angle 1  -->
    <joint name="jaw" type="revolute">
      <parent link="tool_wrist_caudier_link_shaft"/>
      <child link="tool_wrist_caudier_ee_link_0"/>      
      <axis xyz="0 0 1"/>
      <origin rpy="0 0 0" xyz="0 0 0"/>
      <limit lower="-2.5707" upper="2.5707" velocity=".4" effort="1000"/>
    </joint>

    <!-- link 7-0: Outer open angle virtual -->
    <link name="tool_wrist_caudier_ee_link_0">
      <collision>
        <origin rpy="0 0 0" xyz="0 0 0"/>
        <geometry>          
          <box size="0 0 0" />
        </geometry>
      </collision>
      <visual>
        <origin rpy="0 0 0" xyz="0 0 0"/>
        <geometry>          
          <box size="0 0 0" />
        </geometry>
      </visual>
    <inertial>
      <mass value="0.0"/>
      <inertia ixx="0.0" ixy="0.0" ixz="0.0" iyy="0" iyz="0.0" izz="0.0"/>
    </inertial>
    </link>

    <!-- joint 7-1: Outer open angle 1 -->
    <joint name="jaw_mimic_1" type="revolute">
      <parent link="tool_wrist_caudier_link_shaft"/>
      <child link="tool_wrist_caudier_link_2_left"/>
      <axis xyz="0 0 1"/>
      <origin rpy="0 0 0" xyz="0 0 0"/>
      <limit lower="-2.5707" upper="2.5707" velocity=".4" effort="1000"/>
      <mimic joint="jaw" multiplier="0.5"/>
    </joint>

    <!-- link 7-1: Outer open angle link 1 -->
    <link name="tool_wrist_caudier_link_2_left">
      <visual>
        <origin rpy="0.0 0 0.0" xyz="0 0 0.00195"/>
        <geometry>
          <mesh filename="package://rrbot_description/meshes/tool_wrist_caudier_link_2.stl"/>
        </geometry>
      </visual>     
      <collision>
        <origin rpy="0.0 0 0.0" xyz="0 0 0.00195"/>
        <geometry>
          <mesh filename="package://rrbot_description/meshes/tool_wrist_caudier_link_2.stl"/>
        </geometry>
      </collision>    
    <inertial>
      <mass value="0.5"/>
      <inertia ixx="1.0" ixy="1.0" ixz="0.0" iyy="1.0" iyz="1.0" izz="1.0"/>
    </inertial>
    </link>

    <!-- joint 7-2: Outer open angle 2  -->
    <joint name="jaw_mimic_2" type="revolute">
      <parent link="tool_wrist_caudier_link_shaft"/>
      <child link="tool_wrist_caudier_link_2_right"/>
      <axis xyz="0 0 1"/>
      <origin rpy="3.1415926 0 0" xyz="0 0 0"/>
      <limit lower="-2.5707" upper="2.5707" velocity=".4" effort="1000"/>
      <mimic joint="jaw" multiplier="0.5"/>
    </joint>

    <!-- link 7-2: Outer open angle link 2 -->
    <link name="tool_wrist_caudier_link_2_right">
      <visual>
        <origin rpy="0 0 -3.1415926" xyz="0 0 0.00195"/>
        <geometry>
          <mesh filename="package://rrbot_description/meshes/tool_wrist_caudier_link_2.stl"/>
        </geometry>
      </visual>      
      <collision>
        <origin rpy="0 0 -3.1415926" xyz="0 0 0.00195"/>
        <geometry>
          <mesh filename="package://rrbot_description/meshes/tool_wrist_caudier_link_2.stl"/>
        </geometry>
      </collision> 
    <inertial>
      <mass value="0.5"/>
      <inertia ixx="1.0" ixy="1.0" ixz="0.0" iyy="1.0" iyz="1.0" izz="1.0"/>
    </inertial>
    </link>

    <!-- tool tip   -->
    <joint name="tool_wrist_caudier_ee" type="fixed">
      <parent link="tool_wrist_caudier_link_shaft"/>
      <child link="tool_wrist_caudier_ee_link"/>      
      <origin rpy="0.0 1.5708 1.5708" xyz="0 0 0"/>      
    </joint>

    <!-- link 6-3:  -->
    <link name="tool_wrist_caudier_ee_link" />   

  <transmission name="tran1">
    <type>transmission_interface/SimpleTransmission</type>
    <joint name="outer_wrist_yaw">
      <hardwareInterface>EffortJointInterface</hardwareInterface>
    </joint>
    <actuator name="motor1">
      <hardwareInterface>EffortJointInterface</hardwareInterface>
      <mechanicalReduction>1</mechanicalReduction>
    </actuator>
  </transmission>

  <transmission name="tran3">
    <type>transmission_interface/SimpleTransmission</type>
    <joint name="jaw_mimic_1">
      <hardwareInterface>EffortJointInterface</hardwareInterface>
    </joint>
    <actuator name="motor3">
      <hardwareInterface>EffortJointInterface</hardwareInterface>
      <mechanicalReduction>1</mechanicalReduction>
    </actuator>
  </transmission>

  <transmission name="tran4">
    <type>transmission_interface/SimpleTransmission</type>
    <joint name="jaw_mimic_2">
      <hardwareInterface>EffortJointInterface</hardwareInterface>
    </joint>
    <actuator name="motor4">
      <hardwareInterface>EffortJointInterface</hardwareInterface>
      <mechanicalReduction>1</mechanicalReduction>
    </actuator>
  </transmission>

</robot>
